Workbook

Sheet Анализ
A2: Анализ продаж магазина за 2023 год
A4: Показатель | B4: Значение
A5: Общая выручка, ден. ед. | B5: =SUM('sales_data'!H2:H1201) -> 5.0116269e+08
A6: Количество заказов | B6: =COUNTA('sales_data'!A2:A1201) -> 1200
A7: Продано единиц | B7: =SUM('sales_data'!F2:F1201) -> 6646
A8: Месяц максимальной выручки | B8: =INDEX('По месяцам'!A5:A16,MATCH(MAX('По месяцам'!B5:B16),'По месяцам'!B5:B16,0)) -> 2023-12
A10: Топ-5 товаров по количеству
A11: Товар | B11: Количество, шт. | C11: Выручка, ден. ед.
A12: =INDEX($A$51:$A$66,MATCH(1,$D$51:$D$66,0)) -> Полотенце | B12: =INDEX($B$51:$B$66,MATCH(1,$D$51:$D$66,0)) -> 507 | C12: =INDEX($C$51:$C$66,MATCH(1,$D$51:$D$66,0)) -> 36653170
A13: =INDEX($A$51:$A$66,MATCH(2,$D$51:$D$66,0)) -> Кофе | B13: =INDEX($B$51:$B$66,MATCH(2,$D$51:$D$66,0)) -> 493 | C13: =INDEX($C$51:$C$66,MATCH(2,$D$51:$D$66,0)) -> 37886517
A14: =INDEX($A$51:$A$66,MATCH(3,$D$51:$D$66,0)) -> Хлеб | B14: =INDEX($B$51:$B$66,MATCH(3,$D$51:$D$66,0)) -> 488 | C14: =INDEX($C$51:$C$66,MATCH(3,$D$51:$D$66,0)) -> 35775497
A15: =INDEX($A$51:$A$66,MATCH(4,$D$51:$D$66,0)) -> Куртка | B15: =INDEX($B$51:$B$66,MATCH(4,$D$51:$D$66,0)) -> 476 | C15: =INDEX($C$51:$C$66,MATCH(4,$D$51:$D$66,0)) -> 35283630
A16: =INDEX($A$51:$A$66,MATCH(5,$D$51:$D$66,0)) -> Плед | B16: =INDEX($B$51:$B$66,MATCH(5,$D$51:$D$66,0)) -> 461 | C16: =INDEX($C$51:$C$66,MATCH(5,$D$51:$D$66,0)) -> 33304959
A19: Категории и средняя цена
A20: Категория | B20: Количество, шт. | C20: Выручка, ден. ед. | D20: Средняя Price, ден. ед.
A21: Одежда | B21: =SUMIFS('sales_data'!$F$2:$F$1201,'sales_data'!$C$2:$C$1201,A21) -> 1575 | C21: =SUMIFS('sales_data'!$H$2:$H$1201,'sales_data'!$C$2:$C$1201,A21) -> 1.1175823e+08 | D21: =AVERAGEIFS('sales_data'!$E$2:$E$1201,'sales_data'!$C$2:$C$1201,A21) -> 72849.669
A22: Продукты | B22: =SUMIFS('sales_data'!$F$2:$F$1201,'sales_data'!$C$2:$C$1201,A22) -> 1789 | C22: =SUMIFS('sales_data'!$H$2:$H$1201,'sales_data'!$C$2:$C$1201,A22) -> 1.4000141e+08 | D22: =AVERAGEIFS('sales_data'!$E$2:$E$1201,'sales_data'!$C$2:$C$1201,A22) -> 77594.708
A23: Товары для дома | B23: =SUMIFS('sales_data'!$F$2:$F$1201,'sales_data'!$C$2:$C$1201,A23) -> 1842 | C23: =SUMIFS('sales_data'!$H$2:$H$1201,'sales_data'!$C$2:$C$1201,A23) -> 1.362903e+08 | D23: =AVERAGEIFS('sales_data'!$E$2:$E$1201,'sales_data'!$C$2:$C$1201,A23) -> 72445.208
A24: Электроника | B24: =SUMIFS('sales_data'!$F$2:$F$1201,'sales_data'!$C$2:$C$1201,A24) -> 1440 | C24: =SUMIFS('sales_data'!$H$2:$H$1201,'sales_data'!$C$2:$C$1201,A24) -> 1.1311276e+08 | D24: =AVERAGEIFS('sales_data'!$E$2:$E$1201,'sales_data'!$C$2:$C$1201,A24) -> 77994.988
A26: Выручка по регионам
A27: Регион | B27: Выручка, ден. ед.
A28: Новосибирск | B28: =SUMIFS('sales_data'!$H$2:$H$1201,'sales_data'!$G$2:$G$1201,A28) -> 92400036
A29: Московская область | B29: =SUMIFS('sales_data'!$H$2:$H$1201,'sales_data'!$G$2:$G$1201,A29) -> 89163062
A30: Казань | B30: =SUMIFS('sales_data'!$H$2:$H$1201,'sales_data'!$G$2:$G$1201,A30) -> 84948316
A31: Екатеринбург | B31: =SUMIFS('sales_data'!$H$2:$H$1201,'sales_data'!$G$2:$G$1201,A31) -> 78621029
A32: Санкт‑Петербург | B32: =SUMIFS('sales_data'!$H$2:$H$1201,'sales_data'!$G$2:$G$1201,A32) -> 78402886
A33: Москва | B33: =SUMIFS('sales_data'!$H$2:$H$1201,'sales_data'!$G$2:$G$1201,A33) -> 77627366
A35: Топ-10 заказов по сумме Total
A36: OrderID | B36: Дата | C36: Товар | D36: Категория | E36: Регион | F36: Количество, шт. | G36: Total, ден. ед.
A37: =INDEX('sales_data'!$A$2:$A$1201,MATCH(1,'sales_data'!$J$2:$J$1201,0)) -> 355 | B37: =INDEX('sales_data'!$B$2:$B$1201,MATCH(1,'sales_data'!$J$2:$J$1201,0)) -> 45071 | C37: =INDEX('sales_data'!$D$2:$D$1201,MATCH(1,'sales_data'!$J$2:$J$1201,0)) -> Подушка | D37: =INDEX('sales_data'!$C$2:$C$1201,MATCH(1,'sales_data'!$J$2:$J$1201,0)) -> Товары для дома | E37: =INDEX('sales_data'!$G$2:$G$1201,MATCH(1,'sales_data'!$J$2:$J$1201,0)) -> Санкт‑Петербург | F37: =INDEX('sales_data'!$F$2:$F$1201,MATCH(1,'sales_data'!$J$2:$J$1201,0)) -> 10 | G37: =INDEX('sales_data'!$H$2:$H$1201,MATCH(1,'sales_data'!$J$2:$J$1201,0)) -> 1478726.6
A38: =INDEX('sales_data'!$A$2:$A$1201,MATCH(2,'sales_data'!$J$2:$J$1201,0)) -> 915 | B38: =INDEX('sales_data'!$B$2:$B$1201,MATCH(2,'sales_data'!$J$2:$J$1201,0)) -> 45043 | C38: =INDEX('sales_data'!$D$2:$D$1201,MATCH(2,'sales_data'!$J$2:$J$1201,0)) -> Кроссовки | D38: =INDEX('sales_data'!$C$2:$C$1201,MATCH(2,'sales_data'!$J$2:$J$1201,0)) -> Одежда | E38: =INDEX('sales_data'!$G$2:$G$1201,MATCH(2,'sales_data'!$J$2:$J$1201,0)) -> Санкт‑Петербург | F38: =INDEX('sales_data'!$F$2:$F$1201,MATCH(2,'sales_data'!$J$2:$J$1201,0)) -> 10 | G38: =INDEX('sales_data'!$H$2:$H$1201,MATCH(2,'sales_data'!$J$2:$J$1201,0)) -> 1458392.3
A39: =INDEX('sales_data'!$A$2:$A$1201,MATCH(3,'sales_data'!$J$2:$J$1201,0)) -> 3 | B39: =INDEX('sales_data'!$B$2:$B$1201,MATCH(3,'sales_data'!$J$2:$J$1201,0)) -> 44939 | C39: =INDEX('sales_data'!$D$2:$D$1201,MATCH(3,'sales_data'!$J$2:$J$1201,0)) -> Полотенце | D39: =INDEX('sales_data'!$C$2:$C$1201,MATCH(3,'sales_data'!$J$2:$J$1201,0)) -> Товары для дома | E39: =INDEX('sales_data'!$G$2:$G$1201,MATCH(3,'sales_data'!$J$2:$J$1201,0)) -> Новосибирск | F39: =INDEX('sales_data'!$F$2:$F$1201,MATCH(3,'sales_data'!$J$2:$J$1201,0)) -> 10 | G39: =INDEX('sales_data'!$H$2:$H$1201,MATCH(3,'sales_data'!$J$2:$J$1201,0)) -> 1457462.1
A40: =INDEX('sales_data'!$A$2:$A$1201,MATCH(4,'sales_data'!$J$2:$J$1201,0)) -> 1143 | B40: =INDEX('sales_data'!$B$2:$B$1201,MATCH(4,'sales_data'!$J$2:$J$1201,0)) -> 44949 | C40: =INDEX('sales_data'!$D$2:$D$1201,MATCH(4,'sales_data'!$J$2:$J$1201,0)) -> Планшет | D40: =INDEX('sales_data'!$C$2:$C$1201,MATCH(4,'sales_data'!$J$2:$J$1201,0)) -> Электроника | E40: =INDEX('sales_data'!$G$2:$G$1201,MATCH(4,'sales_data'!$J$2:$J$1201,0)) -> Санкт‑Петербург | F40: =INDEX('sales_data'!$F$2:$F$1201,MATCH(4,'sales_data'!$J$2:$J$1201,0)) -> 10 | G40: =INDEX('sales_data'!$H$2:$H$1201,MATCH(4,'sales_data'!$J$2:$J$1201,0)) -> 1456306.9
A41: =INDEX('sales_data'!$A$2:$A$1201,MATCH(5,'sales_data'!$J$2:$J$1201,0)) -> 988 | B41: =INDEX('sales_data'!$B$2:$B$1201,MATCH(5,'sales_data'!$J$2:$J$1201,0)) -> 45097 | C41: =INDEX('sales_data'!$D$2:$D$1201,MATCH(5,'sales_data'!$J$2:$J$1201,0)) -> Кофе | D41: =INDEX('sales_data'!$C$2:$C$1201,MATCH(5,'sales_data'!$J$2:$J$1201,0)) -> Продукты | E41: =INDEX('sales_data'!$G$2:$G$1201,MATCH(5,'sales_data'!$J$2:$J$1201,0)) -> Москва | F41: =INDEX('sales_data'!$F$2:$F$1201,MATCH(5,'sales_data'!$J$2:$J$1201,0)) -> 10 | G41: =INDEX('sales_data'!$H$2:$H$1201,MATCH(5,'sales_data'!$J$2:$J$1201,0)) -> 1413023.6
A42: =INDEX('sales_data'!$A$2:$A$1201,MATCH(6,'sales_data'!$J$2:$J$1201,0)) -> 29 | B42: =INDEX('sales_data'!$B$2:$B$1201,MATCH(6,'sales_data'!$J$2:$J$1201,0)) -> 45014 | C42: =INDEX('sales_data'!$D$2:$D$1201,MATCH(6,'sales_data'!$J$2:$J$1201,0)) -> Планшет | D42: =INDEX('sales_data'!$C$2:$C$1201,MATCH(6,'sales_data'!$J$2:$J$1201,0)) -> Электроника | E42: =INDEX('sales_data'!$G$2:$G$1201,MATCH(6,'sales_data'!$J$2:$J$1201,0)) -> Екатеринбург | F42: =INDEX('sales_data'!$F$2:$F$1201,MATCH(6,'sales_data'!$J$2:$J$1201,0)) -> 10 | G42: =INDEX('sales_data'!$H$2:$H$1201,MATCH(6,'sales_data'!$J$2:$J$1201,0)) -> 1394792.9
A43: =INDEX('sales_data'!$A$2:$A$1201,MATCH(7,'sales_data'!$J$2:$J$1201,0)) -> 354 | B43: =INDEX('sales_data'!$B$2:$B$1201,MATCH(7,'sales_data'!$J$2:$J$1201,0)) -> 44989 | C43: =INDEX('sales_data'!$D$2:$D$1201,MATCH(7,'sales_data'!$J$2:$J$1201,0)) -> Наушники | D43: =INDEX('sales_data'!$C$2:$C$1201,MATCH(7,'sales_data'!$J$2:$J$1201,0)) -> Электроника | E43: =INDEX('sales_data'!$G$2:$G$1201,MATCH(7,'sales_data'!$J$2:$J$1201,0)) -> Московская область | F43: =INDEX('sales_data'!$F$2:$F$1201,MATCH(7,'sales_data'!$J$2:$J$1201,0)) -> 10 | G43: =INDEX('sales_data'!$H$2:$H$1201,MATCH(7,'sales_data'!$J$2:$J$1201,0)) -> 1367179.1
A44: =INDEX('sales_data'!$A$2:$A$1201,MATCH(8,'sales_data'!$J$2:$J$1201,0)) -> 282 | B44: =INDEX('sales_data'!$B$2:$B$1201,MATCH(8,'sales_data'!$J$2:$J$1201,0)) -> 45276 | C44: =INDEX('sales_data'!$D$2:$D$1201,MATCH(8,'sales_data'!$J$2:$J$1201,0)) -> Шоколад | D44: =INDEX('sales_data'!$C$2:$C$1201,MATCH(8,'sales_data'!$J$2:$J$1201,0)) -> Продукты | E44: =INDEX('sales_data'!$G$2:$G$1201,MATCH(8,'sales_data'!$J$2:$J$1201,0)) -> Казань | F44: =INDEX('sales_data'!$F$2:$F$1201,MATCH(8,'sales_data'!$J$2:$J$1201,0)) -> 10 | G44: =INDEX('sales_data'!$H$2:$H$1201,MATCH(8,'sales_data'!$J$2:$J$1201,0)) -> 1338795.6
A45: =INDEX('sales_data'!$A$2:$A$1201,MATCH(9,'sales_data'!$J$2:$J$1201,0)) -> 401 | B45: =INDEX('sales_data'!$B$2:$B$1201,MATCH(9,'sales_data'!$J$2:$J$1201,0)) -> 45289 | C45: =INDEX('sales_data'!$D$2:$D$1201,MATCH(9,'sales_data'!$J$2:$J$1201,0)) -> Куртка | D45: =INDEX('sales_data'!$C$2:$C$1201,MATCH(9,'sales_data'!$J$2:$J$1201,0)) -> Одежда | E45: =INDEX('sales_data'!$G$2:$G$1201,MATCH(9,'sales_data'!$J$2:$J$1201,0)) -> Екатеринбург | F45: =INDEX('sales_data'!$F$2:$F$1201,MATCH(9,'sales_data'!$J$2:$J$1201,0)) -> 10 | G45: =INDEX('sales_data'!$H$2:$H$1201,MATCH(9,'sales_data'!$J$2:$J$1201,0)) -> 1336724.7
A46: =INDEX('sales_data'!$A$2:$A$1201,MATCH(10,'sales_data'!$J$2:$J$1201,0)) -> 272 | B46: =INDEX('sales_data'!$B$2:$B$1201,MATCH(10,'sales_data'!$J$2:$J$1201,0)) -> 45193 | C46: =INDEX('sales_data'!$D$2:$D$1201,MATCH(10,'sales_data'!$J$2:$J$1201,0)) -> Джинсы | D46: =INDEX('sales_data'!$C$2:$C$1201,MATCH(10,'sales_data'!$J$2:$J$1201,0)) -> Одежда | E46: =INDEX('sales_data'!$G$2:$G$1201,MATCH(10,'sales_data'!$J$2:$J$1201,0)) -> Московская область | F46: =INDEX('sales_data'!$F$2:$F$1201,MATCH(10,'sales_data'!$J$2:$J$1201,0)) -> 10 | G46: =INDEX('sales_data'!$H$2:$H$1201,MATCH(10,'sales_data'!$J$2:$J$1201,0)) -> 1326438.2
A49: Продажи всех товаров
...

Sheet По месяцам
A2: Помесячная выручка и категории
A4: Month | B4: Сумма Total | D4: Месяц | E4: Одежда | F4: Продукты | G4: Товары для дома | H4: Электроника
A5: 2023-01 | B5: 40161033 | D5: 2023-01 | E5: =SUMIFS('sales_data'!$H$2:$H$1201,'sales_data'!$I$2:$I$1201,$D5,'sales_data'!$C$2:$C$1201,E$4) -> 6643127.9 | F5: =SUMIFS('sales_data'!$H$2:$H$1201,'sales_data'!$I$2:$I$1201,$D5,'sales_data'!$C$2:$C$1201,F$4) -> 3971557 | G5: =SUMIFS('sales_data'!$H$2:$H$1201,'sales_data'!$I$2:$I$1201,$D5,'sales_data'!$C$2:$C$1201,G$4) -> 17160111 | H5: =SUMIFS('sales_data'!$H$2:$H$1201,'sales_data'!$I$2:$I$1201,$D5,'sales_data'!$C$2:$C$1201,H$4) -> 12386236
A6: 2023-02 | B6: 37386975 | D6: 2023-02 | E6: =SUMIFS('sales_data'!$H$2:$H$1201,'sales_data'!$I$2:$I$1201,$D6,'sales_data'!$C$2:$C$1201,E$4) -> 7014828.2 | F6: =SUMIFS('sales_data'!$H$2:$H$1201,'sales_data'!$I$2:$I$1201,$D6,'sales_data'!$C$2:$C$1201,F$4) -> 9997617.2 | G6: =SUMIFS('sales_data'!$H$2:$H$1201,'sales_data'!$I$2:$I$1201,$D6,'sales_data'!$C$2:$C$1201,G$4) -> 6471064.9 | H6: =SUMIFS('sales_data'!$H$2:$H$1201,'sales_data'!$I$2:$I$1201,$D6,'sales_data'!$C$2:$C$1201,H$4) -> 13903465
A7: 2023-03 | B7: 38032396 | D7: 2023-03 | E7: =SUMIFS('sales_data'!$H$2:$H$1201,'sales_data'!$I$2:$I$1201,$D7,'sales_data'!$C$2:$C$1201,E$4) -> 6623059.4 | F7: =SUMIFS('sales_data'!$H$2:$H$1201,'sales_data'!$I$2:$I$1201,$D7,'sales_data'!$C$2:$C$1201,F$4) -> 9811857.1 | G7: =SUMIFS('sales_data'!$H$2:$H$1201,'sales_data'!$I$2:$I$1201,$D7,'sales_data'!$C$2:$C$1201,G$4) -> 9433317.4 | H7: =SUMIFS('sales_data'!$H$2:$H$1201,'sales_data'!$I$2:$I$1201,$D7,'sales_data'!$C$2:$C$1201,H$4) -> 12164162
A8: 2023-04 | B8: 42708720 | D8: 2023-04 | E8: =SUMIFS('sales_data'!$H$2:$H$1201,'sales_data'!$I$2:$I$1201,$D8,'sales_data'!$C$2:$C$1201,E$4) -> 12610602 | F8: =SUMIFS('sales_data'!$H$2:$H$1201,'sales_data'!$I$2:$I$1201,$D8,'sales_data'!$C$2:$C$1201,F$4) -> 10859145 | G8: =SUMIFS('sales_data'!$H$2:$H$1201,'sales_data'!$I$2:$I$1201,$D8,'sales_data'!$C$2:$C$1201,G$4) -> 12889055 | H8: =SUMIFS('sales_data'!$H$2:$H$1201,'sales_data'!$I$2:$I$1201,$D8,'sales_data'!$C$2:$C$1201,H$4) -> 6349917
A9: 2023-05 | B9: 41600638 | D9: 2023-05 | E9: =SUMIFS('sales_data'!$H$2:$H$1201,'sales_data'!$I$2:$I$1201,$D9,'sales_data'!$C$2:$C$1201,E$4) -> 7162845.6 | F9: =SUMIFS('sales_data'!$H$2:$H$1201,'sales_data'!$I$2:$I$1201,$D9,'sales_data'!$C$2:$C$1201,F$4) -> 12558813 | G9: =SUMIFS('sales_data'!$H$2:$H$1201,'sales_data'!$I$2:$I$1201,$D9,'sales_data'!$C$2:$C$1201,G$4) -> 14664693 | H9: =SUMIFS('sales_data'!$H$2:$H$1201,'sales_data'!$I$2:$I$1201,$D9,'sales_data'!$C$2:$C$1201,H$4) -> 7214286.3
A10: 2023-06 | B10: 39883809 | D10: 2023-06 | E10: =SUMIFS('sales_data'!$H$2:$H$1201,'sales_data'!$I$2:$I$1201,$D10,'sales_data'!$C$2:$C$1201,E$4) -> 8721687.8 | F10: =SUMIFS('sales_data'!$H$2:$H$1201,'sales_data'!$I$2:$I$1201,$D10,'sales_data'!$C$2:$C$1201,F$4) -> 10625612 | G10: =SUMIFS('sales_data'!$H$2:$H$1201,'sales_data'!$I$2:$I$1201,$D10,'sales_data'!$C$2:$C$1201,G$4) -> 14254148 | H10: =SUMIFS('sales_data'!$H$2:$H$1201,'sales_data'!$I$2:$I$1201,$D10,'sales_data'!$C$2:$C$1201,H$4) -> 6282360.6
A11: 2023-07 | B11: 38890200 | D11: 2023-07 | E11: =SUMIFS('sales_data'!$H$2:$H$1201,'sales_data'!$I$2:$I$1201,$D11,'sales_data'!$C$2:$C$1201,E$4) -> 9265537.5 | F11: =SUMIFS('sales_data'!$H$2:$H$1201,'sales_data'!$I$2:$I$1201,$D11,'sales_data'!$C$2:$C$1201,F$4) -> 17240291 | G11: =SUMIFS('sales_data'!$H$2:$H$1201,'sales_data'!$I$2:$I$1201,$D11,'sales_data'!$C$2:$C$1201,G$4) -> 5665645 | H11: =SUMIFS('sales_data'!$H$2:$H$1201,'sales_data'!$I$2:$I$1201,$D11,'sales_data'!$C$2:$C$1201,H$4) -> 6718727
A12: 2023-08 | B12: 39979970 | D12: 2023-08 | E12: =SUMIFS('sales_data'!$H$2:$H$1201,'sales_data'!$I$2:$I$1201,$D12,'sales_data'!$C$2:$C$1201,E$4) -> 10301861 | F12: =SUMIFS('sales_data'!$H$2:$H$1201,'sales_data'!$I$2:$I$1201,$D12,'sales_data'!$C$2:$C$1201,F$4) -> 16729200 | G12: =SUMIFS('sales_data'!$H$2:$H$1201,'sales_data'!$I$2:$I$1201,$D12,'sales_data'!$C$2:$C$1201,G$4) -> 7692493.2 | H12: =SUMIFS('sales_data'!$H$2:$H$1201,'sales_data'!$I$2:$I$1201,$D12,'sales_data'!$C$2:$C$1201,H$4) -> 5256415.9
A13: 2023-09 | B13: 40218791 | D13: 2023-09 | E13: =SUMIFS('sales_data'!$H$2:$H$1201,'sales_data'!$I$2:$I$1201,$D13,'sales_data'!$C$2:$C$1201,E$4) -> 11181324 | F13: =SUMIFS('sales_data'!$H$2:$H$1201,'sales_data'!$I$2:$I$1201,$D13,'sales_data'!$C$2:$C$1201,F$4) -> 9535162 | G13: =SUMIFS('sales_data'!$H$2:$H$1201,'sales_data'!$I$2:$I$1201,$D13,'sales_data'!$C$2:$C$1201,G$4) -> 11780102 | H13: =SUMIFS('sales_data'!$H$2:$H$1201,'sales_data'!$I$2:$I$1201,$D13,'sales_data'!$C$2:$C$1201,H$4) -> 7722202.7
A14: 2023-10 | B14: 44104955 | D14: 2023-10 | E14: =SUMIFS('sales_data'!$H$2:$H$1201,'sales_data'!$I$2:$I$1201,$D14,'sales_data'!$C$2:$C$1201,E$4) -> 9532375.9 | F14: =SUMIFS('sales_data'!$H$2:$H$1201,'sales_data'!$I$2:$I$1201,$D14,'sales_data'!$C$2:$C$1201,F$4) -> 12086007 | G14: =SUMIFS('sales_data'!$H$2:$H$1201,'sales_data'!$I$2:$I$1201,$D14,'sales_data'!$C$2:$C$1201,G$4) -> 12829749 | H14: =SUMIFS('sales_data'!$H$2:$H$1201,'sales_data'!$I$2:$I$1201,$D14,'sales_data'!$C$2:$C$1201,H$4) -> 9656822.7
A15: 2023-11 | B15: 46610157 | D15: 2023-11 | E15: =SUMIFS('sales_data'!$H$2:$H$1201,'sales_data'!$I$2:$I$1201,$D15,'sales_data'!$C$2:$C$1201,E$4) -> 11343064 | F15: =SUMIFS('sales_data'!$H$2:$H$1201,'sales_data'!$I$2:$I$1201,$D15,'sales_data'!$C$2:$C$1201,F$4) -> 10918916 | G15: =SUMIFS('sales_data'!$H$2:$H$1201,'sales_data'!$I$2:$I$1201,$D15,'sales_data'!$C$2:$C$1201,G$4) -> 11375927 | H15: =SUMIFS('sales_data'!$H$2:$H$1201,'sales_data'!$I$2:$I$1201,$D15,'sales_data'!$C$2:$C$1201,H$4) -> 12972250
A16: 2023-12 | B16: 51585050 | D16: 2023-12 | E16: =SUMIFS('sales_data'!$H$2:$H$1201,'sales_data'!$I$2:$I$1201,$D16,'sales_data'!$C$2:$C$1201,E$4) -> 11357920 | F16: =SUMIFS('sales_data'!$H$2:$H$1201,'sales_data'!$I$2:$I$1201,$D16,'sales_data'!$C$2:$C$1201,F$4) -> 15667228 | G16: =SUMIFS('sales_data'!$H$2:$H$1201,'sales_data'!$I$2:$I$1201,$D16,'sales_data'!$C$2:$C$1201,G$4) -> 12073990 | H16: =SUMIFS('sales_data'!$H$2:$H$1201,'sales_data'!$I$2:$I$1201,$D16,'sales_data'!$C$2:$C$1201,H$4) -> 12485913
A17: Общий итог | B17: 5.0116269e+08 | D17: Итого | E17: =SUM(E5:E16) -> 1.1175823e+08 | F17: =SUM(F5:F16) -> 1.4000141e+08 | G17: =SUM(G5:G16) -> 1.362903e+08 | H17: =SUM(H5:H16) -> 1.1311276e+08
A20: Рост выручки по категориям
A21: Категория | B21: Январь | C21: Декабрь | D21: Декабрь к январю | E21: Тренд, ден. ед./мес.
A22: Одежда | B22: =E5 -> 6643127.9 | C22: =E16 -> 11357920 | D22: =C22/B22-1 -> 0.70972467 | E22: =SLOPE(E5:E16,$A$31:$A$42) -> 398589.35
A23: Продукты | B23: =F5 -> 3971557 | C23: =F16 -> 15667228 | D23: =C23/B23-1 -> 2.9448579 | E23: =SLOPE(F5:F16,$A$31:$A$42) -> 578213.45
A24: Товары для дома | B24: =G5 -> 17160111 | C24: =G16 -> 12073990 | D24: =C24/B24-1 -> -0.29639212 | E24: =SLOPE(G5:G16,$A$31:$A$42) -> -80693.813
A25: Электроника | B25: =H5 -> 12386236 | C25: =H16 -> 12485913 | D25: =C25/B25-1 -> 0.0080473516 | E25: =SLOPE(H5:H16,$A$31:$A$42) -> -81859.038
A27: Рост за год оценён по декабрю к январю и по тренду всех 12 месяцев.
A28: Сводная A4:B17: после изменения продаж используйте «Данные → Обновить всё».
A30: Номер месяца для расчёта тренда
A31: 1
A32: 2
A33: 3
A34: 4
A35: 5
A36: 6
A37: 7
A38: 8
A39: 9
A40: 10
A41: 11
A42: 12

Sheet sales_data
A1: OrderID | B1: Date | C1: Category | D1: Product | E1: Price | F1: Quantity | G1: CustomerRegion | H1: Total | I1: Month | J1: RevenueRank | L1: Источник: sales_dataset.xlsx
A2: 53 | B2: 44927 | C2: Товары для дома | D2: Плед | E2: 22142.31 | F2: 2 | G2: Новосибирск | H2: =E2*F2 -> 44284.62 | I2: =TEXT(B2,"yyyy-mm") -> 2023-01 | J2: =COUNTIFS($H$2:$H$1201,">"&H2)+COUNTIFS($H$2:H2,H2) -> 1099
A3: 255 | B3: 44927 | C3: Товары для дома | D3: Полотенце | E3: 56803 | F3: 8 | G3: Санкт‑Петербург | H3: =E3*F3 -> 454424 | I3: =TEXT(B3,"yyyy-mm") -> 2023-01 | J3: =COUNTIFS($H$2:$H$1201,">"&H3)+COUNTIFS($H$2:H3,H3) -> 448 | L3: Total = Price × Quantity
A4: 517 | B4: 44927 | C4: Продукты | D4: Кофе | E4: 142755.15 | F4: 4 | G4: Екатеринбург | H4: =E4*F4 -> 571020.6 | I4: =TEXT(B4,"yyyy-mm") -> 2023-01 | J4: =COUNTIFS($H$2:$H$1201,">"&H4)+COUNTIFS($H$2:H4,H4) -> 347 | L4: Month — месяц продажи
A5: 570 | B5: 44927 | C5: Электроника | D5: Ноутбук | E5: 88418.8 | F5: 1 | G5: Казань | H5: =E5*F5 -> 88418.8 | I5: =TEXT(B5,"yyyy-mm") -> 2023-01 | J5: =COUNTIFS($H$2:$H$1201,">"&H5)+COUNTIFS($H$2:H5,H5) -> 998 | L5: RevenueRank — место по сумме заказа
A6: 1053 | B6: 44927 | C6: Товары для дома | D6: Плед | E6: 140698.03 | F6: 6 | G6: Московская область | H6: =E6*F6 -> 844188.18 | I6: =TEXT(B6,"yyyy-mm") -> 2023-01 | J6: =COUNTIFS($H$2:$H$1201,">"&H6)+COUNTIFS($H$2:H6,H6) -> 170
A7: 76 | B7: 44928 | C7: Электроника | D7: Смартфон | E7: 124739.03 | F7: 7 | G7: Санкт‑Петербург | H7: =E7*F7 -> 873173.21 | I7: =TEXT(B7,"yyyy-mm") -> 2023-01 | J7: =COUNTIFS($H$2:$H$1201,">"&H7)+COUNTIFS($H$2:H7,H7) -> 148
A8: 420 | B8: 44928 | C8: Товары для дома | D8: Кружка | E8: 79112.74 | F8: 7 | G8: Казань | H8: =E8*F8 -> 553789.18 | I8: =TEXT(B8,"yyyy-mm") -> 2023-01 | J8: =COUNTIFS($H$2:$H$1201,">"&H8)+COUNTIFS($H$2:H8,H8) -> 364
A9: 450 | B9: 44928 | C9: Электроника | D9: Смартфон | E9: 95400.21 | F9: 5 | G9: Новосибирск | H9: =E9*F9 -> 477001.05 | I9: =TEXT(B9,"yyyy-mm") -> 2023-01 | J9: =COUNTIFS($H$2:$H$1201,">"&H9)+COUNTIFS($H$2:H9,H9) -> 430
A10: 582 | B10: 44928 | C10: Товары для дома | D10: Подушка | E10: 113578.65 | F10: 10 | G10: Екатеринбург | H10: =E10*F10 -> 1135786.5 | I10: =TEXT(B10,"yyyy-mm") -> 2023-01 | J10: =COUNTIFS($H$2:$H$1201,">"&H10)+COUNTIFS($H$2:H10,H10) -> 52
A11: 633 | B11: 44928 | C11: Электроника | D11: Наушники | E11: 98852.45 | F11: 8 | G11: Новосибирск | H11: =E11*F11 -> 790819.6 | I11: =TEXT(B11,"yyyy-mm") -> 2023-01 | J11: =COUNTIFS($H$2:$H$1201,">"&H11)+COUNTIFS($H$2:H11,H11) -> 203
A12: 828 | B12: 44928 | C12: Одежда | D12: Кроссовки | E12: 48883.93 | F12: 4 | G12: Санкт‑Петербург | H12: =E12*F12 -> 195535.72 | I12: =TEXT(B12,"yyyy-mm") -> 2023-01 | J12: =COUNTIFS($H$2:$H$1201,">"&H12)+COUNTIFS($H$2:H12,H12) -> 795
A13: 313 | B13: 44930 | C13: Продукты | D13: Кофе | E13: 19450.02 | F13: 9 | G13: Санкт‑Петербург | H13: =E13*F13 -> 175050.18 | I13: =TEXT(B13,"yyyy-mm") -> 2023-01 | J13: =COUNTIFS($H$2:$H$1201,">"&H13)+COUNTIFS($H$2:H13,H13) -> 820
A14: 459 | B14: 44931 | C14: Одежда | D14: Джинсы | E14: 6809.92 | F14: 4 | G14: Санкт‑Петербург | H14: =E14*F14 -> 27239.68 | I14: =TEXT(B14,"yyyy-mm") -> 2023-01 | J14: =COUNTIFS($H$2:$H$1201,">"&H14)+COUNTIFS($H$2:H14,H14) -> 1135
A15: 572 | B15: 44931 | C15: Электроника | D15: Планшет | E15: 8569.43 | F15: 6 | G15: Санкт‑Петербург | H15: =E15*F15 -> 51416.58 | I15: =TEXT(B15,"yyyy-mm") -> 2023-01 | J15: =COUNTIFS($H$2:$H$1201,">"&H15)+COUNTIFS($H$2:H15,H15) -> 1081
A16: 1133 | B16: 44931 | C16: Одежда | D16: Джинсы | E16: 6417.05 | F16: 9 | G16: Санкт‑Петербург | H16: =E16*F16 -> 57753.45 | I16: =TEXT(B16,"yyyy-mm") -> 2023-01 | J16: =COUNTIFS($H$2:$H$1201,">"&H16)+COUNTIFS($H$2:H16,H16) -> 1065
A17: 60 | B17: 44932 | C17: Товары для дома | D17: Кружка | E17: 45015.51 | F17: 7 | G17: Московская область | H17: =E17*F17 -> 315108.57 | I17: =TEXT(B17,"yyyy-mm") -> 2023-01 | J17: =COUNTIFS($H$2:$H$1201,">"&H17)+COUNTIFS($H$2:H17,H17) -> 621
... A1201: 890 | B1201: 45291 | C1201: Продукты | D1201: Кофе | E1201: 1370.45 | F1201: 9 | G1201: Московская область | H1201: =E1201*F1201 -> 12334.05 | I1201: =TEXT(B1201,"yyyy-mm") -> 2023-12 | J1201: =COUNTIFS($H$2:$H$1201,">"&H1201)+COUNTIFS($H$2:H1201,H1201) -> 1178
